Workbook

Sheet 1. DATOS PREVIOS
B7: IguanaGo! | K7: Tras una época con cada vez un mayor éxito y visibilidad del panorama indie en el mundo de los videojuegos, surgió la idea de crear un título que captase un público general y accesible. Comenzamos queriendo abordarlo con un juego en un estilo 2D plataformas y un metroidvania, pero rápidamente cambiamos al 3D por influencia y capacidades mayores del equipo a algo más ambicioso. Al constar de una IP e idea base grande, nos decantamos por un género concreto y funcional como es el Dungeon Crawler, cogiendo gran influencia de Nintendo y de The Legend of Zelda: Link’s awakening en cuanto a diseño y mecánicas y The Legend of Zelda: Wind Waker en cuanto a banda sonora y sonido. Aparte, queríamos innovar de alguna manera, por lo que probamos por tener un ritmo diferente al habitual, usando nuevas mecánicas y puzles con otro enfoque. La idea surgió de buscar algo más grande con publishers y apoyo, por lo que el enfoque económico y de visibilidad en redes nació con el proyecto para la fundación y crecimiento de nuestra empresa y proyectos.
E12: Alicia Berta Díaz Trabanco
B14: Estudiante en la universidad de UDIT en Desarrollo de videojuegos con varios proyectos gratuitos de videojuegos desarrollados hasta la fecha. Consta de educación secundaria, bachillerato y EBAU, y en educación universitaria, Graduado con el título HND de in Creative Media Production (Game Development) en ESNE Asturias.
E21: Ariel Díaz González
B23: Antigua estudiante de Ingeniería Informática en la Universidad de Oviedo y estudiante en la universidad de UDIT en Desarrollo de videojuegos con varios proyectos gratuitos de videojuegos desarrollados hasta la fecha. Consta de educación secundaria, bachillerato y EBAU, y en educación universitaria, Graduado con el título HND de in Creative Media Production (Game Development) en ESNE Asturias.
E30: Iago López Gómez
B32: Estudiante en la universidad de UDIT en Desarrollo de videojuegos con varios proyectos gratuitos de videojuegos desarrollados hasta la fecha. Consta de educación secundaria, bachillerato y EBAU, y en educación universitaria, Graduado con el título HND de in Creative Media Production (Game Development) en ESNE Asturias. | K32: IguanaGo se presenta como una nueva empresa de videojuegos indie centrada en juegos de PC trabajando desde España, pero con un público objetivo angloparlante, trabajando concretamente en géneros de aventuras (Dungeon crawlers) estilizados con un componente extra de historia inmersiva, con un equipo versátil y resiliente. Queremos ser una empresa afianzada en el mercado internacional centrada en pocos, pero buenos desarrollos, perfeccionando su plantilla, proporcionando seguridad a los inversores y llegando a un público global. Basamos nuestro trabajo interno en el respeto, profesionalidad y orden, junto con la inclusión, seguridad y soporte al cliente.
E39: Lucas García Dominguez
B41: Estudiante en la universidad de UDIT en Desarrollo de videojuegos con varios proyectos gratuitos de videojuegos desarrollados hasta la fecha. Consta de educación secundaria, bachillerato y EBAU, y en educación universitaria, Graduado con el título HND de in Creative Media Production (Game Development) en ESNE Asturias.
E48: Miguel Rodriguez Gallego
B50: Estudiante en la universidad de UDIT en Desarrollo de videojuegos con varios proyectos gratuitos de videojuegos desarrollados hasta la fecha. Consta de educación secundaria, bachillerato y EBAU, y en educación universitaria, Graduado con el título HND de in Creative Media Production (Game Development) en ESNE Asturias.

Sheet 2. P. MARKETING
B7: La competencia en nuestro sector se puede definir en dos grandes grupos: 1º Una multitud de pequeñas empresas y consultores o desarrolladores individuales que – con mayor o menor acierto – intervienen en el mercado. 2º Una minoría de empresas de servicios supervivientes de las puntocom que prestan servicios, sobre todo, a grandes empresas y en algunos casos son subsidiarias de las mismas. En general y salvo honrosas excepciones hay tres características comunes muy relevantes: 1º Dispersión-falta de especialización: Fruto de las necesidades de supervivencia en estos años difíciles, todos los competidores han dispersado su actividad en todos los puntos de lo que podemos denominar el “sector tecnológico” (desde la venta de ordenadores hasta la creación de páginas web). 2º Anclaje en conceptos superados, fruto de los años de las puntocom y muy pocabadaptación-comprensión de las nuevas necesidades. 3º Orientación a la tecnología con notable ausencia del marketing y la comprensión de las necesidades de los usuarios. Por lo que respecta a nuestro posicionamiento como empresa, podemos decir que hay muchos que prometen lo que nosotros ofrecemos pero no existen auténticos especialistas que puedan ofrecer garantías. Principales competidores. Los competidores directos y relevantes en nuestro mercado empresarial son: - AC Asesores tecnológicos - Hig Tech - Thompson LKH - Graorn S.A. - LiveTech | K7: La principal barrera que se encuentra la empresa para su introducción en el mercado es la existencia de competidores muy experimentados con un gran conocimento del mercado que han obtenido tras una larga trayectoria de desarrollo a lo largo de sus 15 años de existencia. A parte del gran conocimiento del mercado, uno de los principales competidores y que actualmente ocupa un puesto de liderazgo dentro del sector, marcando el referente para el resto, desarrolla una excelente estrategia de recursos humanos orientada a la busqueda de perfiles altamente cualificados para la integración dentro de su equipo lo que le lleva a obtener una gran ventaja competitiva frente al resto. | T7: Tal y como hemos indicado, nuestras líneas de producto y servicio tienen tres vértices: 1º Desarrollo e implantación de campañas de marketing en Internet. Naturalmente este servicio se prestará y orientará a medida de las necesidades de cada cliente pero sobre la base de tres opciones: (a) Diseño y planificación de campañas. Incluyendo los conceptos estratégicos y los contenidos. (b) Lanzamiento y gestión de dichas campañas por cuenta del cliente. (c) Optimización de las campañas y-o formación del personal del cliente. Las tres opciones son independientes entre sí pero – lógicamente – pueden estar integradas en un único “pack” con un fee mensual ventajoso para el propio cliente. 2º Desarrollo de los sitios web. Mediante nuestro CMS exclusivo estaremos en condiciones de generar sitios web en un plazo mínimo y a muy bajo coste, incluyendo sitios de e-commerce o que requieran de transacciones económicas. Este servicio también dispondrá de tres opciones o niveles: (a) Diseño y desarrollo técnico del sitio. (b) Desarrollo de contenidos no específicos. (c) Implementación, puesta en marcha y formación de personal del cliente para la gestión del CMS (cliente). 3º Gestión, actualización y mantenimiento de dichos sitios. El tercer eje de servicio se fundamentará en la gestión y el mantenimiento de los sitios generados, gracias a nuestros CMS se dispondrá de un sistema de gestión y control centralizado y de bajo coste que permitirá mecanizar las tareas repetitivas y monitorizar un alto volumen de sitios web dejando el mantenimiento y la actualización específica del sitio al personal responsable del cliente. En esta línea ofreceremos dos productos diferenciales: (a) Mantenimiento técnico y control de las webs en formato “pack por volumen”. (b) Formación del personal del cliente en la gestión del CMS (cliente). Garantía de satisfacción: Un elemento clave en la comercialización de nuestros servicios será la garantía de satisfacción por la cual nos comprometemos al cumplimiento de unos timings, unos estándares de calidad y de reparación de errores. Esta garantía, junto al preceptivo contrato de prestación de servicios será el elemento diferencial concreto más importante de nuestra política comercial. Por otro lado, dicha garantía representará formalmente las obligaciones legales que tenemos (todos) en la prestación de un servicio y establecerá un marco “normativo” en forma positiva para la resolución de potenciales conflictos. En definitiva será un punto fuerte de cara a la confianza del cliente pero no un riesgo adicional para el negocio, todo lo contrario. | AE7: Mi empresa | AG7: Competidor 1 | AI7: Competidor 2 | AL7: Nuestros potenciales clientes son: 1. Todas las empresas radicadas en la Comunidad de Madrid que deseen desarrollar u optimizar sus actividades en la web. 2. Las agencias de publicidad y empresas de servicios a terceros que deseen subcontratar sus campañas. Los targets a los que nos dirigimos son, esencialmente: Clientes - objetivo a corto plazo: 1º Empresas de más de 5 millones de facturación anual que venden sus productos al consumidor. 2º Cualquier empresa o proyecto que haga de Internet un medio esencial. 3º Agencias de publicidad medianas y pequeñas. 4º Cualquier AP que desee subcontratar este servicio. Estos son los targets a los que vamos a dirigir nuestros esfuerzos preferentes, debido a las dificultades de segmentación detallada dirigiremos nuestro esfuerzo publicitario al conjunto de empresas de la comunidad y, naturalmente, no rechazaremos ni perderemos ninguna oportunidad interesante | AU7: Emplazamiento | BM7: Coste mensual por unidades
AC8: Producto | AE8: Consultoría | AG8: Mismo producto | AI8: Mismo producto | AU8: La oficina estará ubicada en la C/ Ramón Alvarez nº 135. 28015 Madrid | BD8: "IguanaGo se posiciona como un bastión en la industria de los videojuegos indie, priorizando la calidad sobre la cantidad. Nuestro enfoque se centra en pocos pero sobresalientes desarrollos, consolidando nuestra presencia en el mercado internacional. Con sede en España pero con visión global, nuestros juegos de PC, especialmente en el género de aventuras (Dungeon crawlers), ofrecen una experiencia inmersiva y rica en historia, diseñada para un público angloparlante exigente. Nuestra empresa se fundamenta en valores de respeto, profesionalismo y organización interna, mientras que hacia nuestros clientes promovemos la inclusión, seguridad y soporte constante. Como un equipo versátil y resiliente, navegamos los desafíos del desarrollo de videojuegos con precisión y determinación, ofreciendo resultados excepcionales que brindan seguridad a nuestros inversores y satisfacen a nuestro público global."
AC9: Precio | AE9: 100 | AG9: 150 | AI9: 200 | BO9: Coste por unidad | BR9: Precio de venta por unidad | BU9: Ingresos por unidades vendidas | BX9: Coste mensual de producción
AC10: Calidad | AE10: Buena | AG10: Media | AI10: Mala | AU10: Transporte público
AC11: Servicio | AE11: ninguno | AG11: ninguno | AI11: ninguno | AU11: Metro Lineas 2, 3, 6 | BM11: Producto A | BO11: 1 | BR11: 10 | BU11: 5 | BX11: 1
AC12: Experiencia | AE12: Por parte del promotor | AG12: 10 años | AI12: 5 años | BM12: Producto B
AC13: Ubicación | AE13: Excelente | AG13: Buena | AI13: Mala | BM13: Producto C
AC14: Métodos venta | AE14: Ferias | AG14: Contactos | AI14: Contactos | AU14: Plano de situación | BM14: Producto D
AC15: Publicidad | AE15: Específica | AG15: Específica | AI15: Específica | BM15: Producto E
AC16: Imagen | AE16: Excelente | AG16: Excelente | AI16: Excelente | BM16: Producto F
BM17: Producto G
AE18: Mi empresa | AG18: Competidor 1 | AI18: Competidor 2 | BM18: Producto H
AC19: Producto | AE19: Asesoria | AG19: Mismo producto | AI19: Mismo producto | BM19: Producto I
AC20: Precio | AE20: 100 | AG20: 150 | AI20: 200 | AL20: Proveedores de sistemas informáticos. | BM20: Producto J
AC21: Calidad | AE21: Buena | AG21: Media | AI21: Mala
AC22: Servicio | AE22: Bueno | AG22: Medio | AI22: Excelente | BM22: Plan de ventas primer año | BR22: ¡Atención! Ventas y compras sin IVA
AC23: Experiencia | AE23: Ninguna | AG23: 2 años | AI23: 3 años
AC24: Ubicación | AE24: Mala | AG24: Buena | AI24: Excelente | BM24: Meses | BO24: 1 | BQ24: 2 | BS24: 3 | BU24: 4 | BW24: 5 | BY24: 6
AC25: Métodos venta | AE25: Contactos | AG25: Contactos | AI25: Contactos | BM25: Ventas | BO25: 25000 | BQ25: 15000 | BS25: 12000 | BU25: 10000 | BW25: 10000 | BY25: 8000
AC26: Publicidad | AE26: Contactos | AG26: Contactos | AI26: Contactos
AC27: Imagen | AE27: Buena | AG27: Media | AI27: Excelente
BM28: Meses | BO28: 7 | BQ28: 8 | BS28: 9 | BU28: 10 | BW28: 11 | BY28: 12
AE29: Mi empresa | AG29: Competidor 1 | AI29: Competidor 2 | BM29: Ventas | BO29: 6000 | BQ29: 6000 | BS29: 15000 | BU29: 7500 | BW29: 5000 | BY29: 6500
AC30: Producto | AE30: Páginas web | AG30: Mismo producto | AI30: Mismo producto
AC31: Precio | AE31: 100 | AG31: 150 | AI31: 300
K32: Ahora mismo ya no existe ninguna duda de que Internet, entre otras cosas, es y será mucho más en los años inmediatos: 1. La herramienta publicitaria y de contacto con los clientes por excelencia para las empresas. 2. El medio publicitario hacia el cual se dirigirá el mayor esfuerzo inversor de las empresas. 3. Un medio incomparable para la creación de nuevos proyectos comerciales. Esto es posible, básicamente, gracias a: 1. La existencia de herramientas muy eficaces y que no existían en los años de las puntocom . 2. El enorme crecimiento de los usuarios de Internet. 3. La saturación y dispersión de los medios tradicionales, que se verá incrementada con la aparición de multitud de canales de la TV digital. 4. Las nuevas tendencias en marketing (fruto de lo anterior) como el “buzzmarketing” y similares que sólo son posibles gracias a la tecnología. 5. El desarrollo de los sistemas de comunicación que ya permite disponer de conexiones a Internet con telefonía móvil. 6. El desarrollo de nuevos productos de electrónica de consumo basados en la conectividad a Internet. Todos estos elementos se traducen – para nuestra empresa – en miles de potenciales clientes Tenemos la experiencia necesaria para aprovechar esta oportunidad con éxito, ya que: 1º Somos especialistas, conocedores de las claves precisas para tener éxito en Internet. 2º Nuestra experiencia es claramente demostrable. Aportaremos experiencia real y demostrable. 3º Nuestros servicios incluirán al alto valor añadido y significarán un enorme ahorro de costes. 4º Podemos ser altamente competitivos en rapidez de respuesta y en precio, fruto de nuestro CMS. 5º Por esa misma razón podemos ofrecer servicios a un amplio espectro de clientes. | AC32: Calidad | AE32: Buena | AG32: Media | AI32: Media | BM32: Plan de compras/costes primer año
AC33: Servicio | AE33: Bueno | AG33: Medio | AI33: Medio | AL33: La comercialización de nuestros servicios se orientará en tres líneas: 1ª Pack integral de campaña, previo presupuesto adecuado al volumen y de coste cerrado. 2º Servicios de coste acumulativo con pago de fee mensual y contratación anual. 3º Servicios puntuales con presupuesto cerrado y adecuado al volumen de compras. Se adjunta lista de servicios y precios según volumen | BG33: Periodicidad | BI33: Duración | BK33: Coste
AC34: Experiencia | AE34: Ninguna | AG34: 2 años | AI34: 2 años | BD34: Venta personal | BG34: Quincenal | BI34: 15 días | BK34: 852 | BM34: Meses | BO34: 1 | BQ34: 2 | BS34: 3 | BU34: 4 | BW34: 5 | BY34: 6
AC35: Ubicación | AE35: Mala | AG35: Buena | AI35: Buena | BD35: Marketing directo | BG35: Mensual | BI35: 1mes | BK35: 15000 | BM35: Compras/costes | BO35: 200 | BQ35: 200 | BS35: 250 | BU35: 250 | BW35: 250 | BY35: 250
AC36: Métodos venta | AE36: Contactos | AG36: Contactos | AI36: Contactos | BD36: Telemarketing | BG36: Ninguna | BI36: Ninguna | BK36: Ninguna
AC37: Publicidad | AE37: Contactos | AG37: Contactos | AI37: Contactos | BD37: Merchandising | BG37: Anual | BI37: 1 año | BK37: 2000
AC38: Imagen | AE38: Buena | AG38: Media | AI38: Media | BD38: Publicidad | BG38: Trimestral | BI38: 3 meses | BK38: 300 | BM38: Meses | BO38: 7 | BQ38: 8 | BS38: 9 | BU38: 10 | BW38: 11 | BY38: 12
BE39: Prensa | BG39: Ninguna | BI39: Ninguna | BK39: Ninguna | BM39: Compras/costes | BO39: 250 | BQ39: 250 | BS39: 250 | BU39: 250 | BW39: 250 | BY39: 250
AE40: Mi empresa | AG40: Competidor 1 | AI40: Competidor 2 | AU40: Fotografías | BE40: Radio | BG40: Ninguna | BI40: Ninguna | BK40: Ninguna
AC41: Producto | AE41: Diseño de campaña | AG41: Mismo producto | AI41: Mismo producto | BE41: Televisión | BG41: Ninguna | BI41: Ninguna | BK41: Ninguna
AC42: Precio | AE42: 150 | AG42: 200 | AI42: 150 | BE42: Internet | BG42: Trimestral | BI42: 3 meses | BK42: 300
AC43: Calidad | AE43: Media | AG43: Mala | AI43: Media | BD43: Concursos | BG43: Ninguna | BI43: Ninguna | BK43: Ninguna | BM43: Total de ventas y compras primer año
AC44: Servicio | AE44: Medio | AG44: Excelente | AI44: ninguno | BD44: Premios | BG44: Ninguna | BI44: Ninguna | BK44: Ninguna
AC45: Experiencia | AE45: 2 años | AG45: 3 años | AI45: 10 años | BD45: Descuentos | BG45: Mensual | BI45: 1 mes | BK45: 2000 | BO45: AÑO 1
AC46: Ubicación | AE46: Buena | AG46: Excelente | AI46: Buena | BD46: Paquetes promocionales | BG46: Mensual | BI46: ninguno | BK46: ninguno | BM46: Ventas | BO46: =SUM(BO25:BZ25)+SUM(BO29:BZ29) -> 126000
...

Sheet 3. P. OPERACIONES
F5: 40634
K7: 1º Desarrollo CMS: Partimos de una base ya desarrollada por nuestro equipo, con lo cual sólo serán< precisos una serie de ajustes enfocados a su función eminentemente productiva. Prevemos un desarrollo de 6 meses y un período de prueba/ajuste de 4 meses adicionales. El desarrollo lo realizará el actual equipo técnico con programadores subcontratados en el exterior. 2º Desarrollo webs propias: Prevemos un desarrollo de 6 meses y un período de prueba/ajuste de 2 meses adicionales. El desarrollo lo realizará el actual equipo técnico con programadores subcontratados en el exterior. 3º Selección y formación del personal inicial: La selección correrá a cargo de una empresa especializada de reconocido prestigio en Madrid. Prevemos 4 meses de proceso de selección. El personal contratado recibirá un curso de formación de diversa intensidad según el puesto de trabajo. Los cursos de formación se desarrollarán en el primer mes de actividad, salvo los cursos para la fuerza de ventas que se desarrollarán en el mes anterior. 4º Infraestructuras: Prevemos el alquiler de las oficinas 7 meses antes del inicio de la actividad comercial, desde dichas instalaciones y de forma provisional se harán los trabajos preparatorios. Las instalaciones y el equipamiento final de las oficinas se realizarán los tres meses anteriores al lanzamiento comercial. 5º Inversiones: Los pedidos se realizarán durante los 5 meses anteriores para que puedan estar disponibles en el momento del inicio de la actividad. Fechas clave: 1º Inicio desarrollos: CMS y webs corporativas MES -7 Coincidiendo con el alquiler de las oficinas y el inicio de la contratación de servicios y los pedidos. 2º Selección de personal: Inicio MES -4 3º Inicio de la actividad comercial: MES 1 4º Fase de lanzamiento del negocio: MESES 1,2 y 3. | T7: Los recursos con los que dispone actualmente la empresa son: 3 equipos informáticos y el diseño y desarrollo del software para el diseño y venta de la aplicación.
B9: El objetivo de nuestro Plan especial de Lanzamiento es obtener notoriedad desde el primer minuto. No somos una empresa más, queremos hacernos notar en todos los ámbitos y para ello desarrollaremos una suma de acciones y mini-campañas que pretenden generar un efecto novedad positivo para nuestros intereses. Nuestros objetivos son: 1.- Hacernos notar: que las empresas de nuestro entorno nos conozcan a la mayor brevedad. 2.- Posicionarnos desde el primer momento como una compañía muy relevante que aporta calidad y valor añadido
K32: Los condicionantes a los que tendrá que hacer frente la empresa se deberán a posibles imprevistos que surgan en los siguientes campos: retraso en la obtención de la licencia para el despacho, demora en la aprobación de las lineas financieras solicitadas así como demora en todas las tareas referentes al acondicionamiento del local por parte de los distintos agentes que serán contratados para la realización de las mismas. | T32: La empresa cuenta con los siguientes recursos inmateriales: la obtención de una patente para la aplicación informática.

Sheet 4. P. REC. HUMANOS
B7: Area 1 | D7: Dependientes de la Dirección General: | K7: Dirección de la empresa. - Administración de la empresa: La empresa estará dirigida por un Consejo de Administración formado por 5 miembros y un secretario no consejero. - Composición inicial: Presidente: Julián Varcárcel. Consejero Delegado: Luís García. Vocal: Helena Sánchez 2 vocales a disposición de nuevos inversores. Secretario no consejero: Jesús Román. - Dirección operativa: Comité de Dirección Director General: Luís García. Director Financiero: pendiente de selección. Director de Marketing y Ventas: Jesús Román. Director Técnico: Helena Sánchez. Directora de Proyectos de Desarrollo: Juana Fernández. | T7: Trabajador 1
T8: Puesto | W8: Alicia Berta Díaz Trabanco
B9: Funciones | T9: Funciones
B10: • Atención al Cliente. • Control de Calidad | T10: • Modelado de props •Modelado de escenario
T12: Perfil | V12: Artista | Y12: Salario | AA12: 1323
B13: Puestos de trabajo | T13: Cat.profesional | V13: Artista | Y13: Beneficios sociales | AA13: Ninguno
B14: 1 puesto de trabajo. | T14: Tipo contrato | V14: Contrato indefinido | Y14: Vacaciones | AA14: 15 días
T15: Periodo prueba | V15: 6 meses | Y15: Costes seg. social | AA15: 436.59
T16: Horario | V16: 08:00 - 15:00 | Y16: Costes s.s. autónom. | AA16: 0
T17: Jornada | V17: Completa | Y17: Fecha de inicio | AA17: 40634
B19: Area 2 | D19: Dependientes de la Dirección Financiera: | T19: Trabajador 2
T20: Puesto | W20: Ariel Díaz Gonzalez
B21: Funciones | T21: Funciones
B22: • Administración y finanzas. • Recursos Humanos y formación. • Servicios y mantenimiento | T22: •Dirección de arte •Modelado de personajes •Retopologia de personajes •Rigging de personajes
T23: •Animación de personajes
T24: Perfil | V24: Artista | Y24: Salario | AA24: 1323
B25: Puestos de trabajo | T25: Cat.profesional | V25: Artista principal | Y25: Beneficios sociales | AA25: Ninguno
B26: 1 puesto de trabajo. | T26: Tipo contrato | V26: Contrato indefinido | Y26: Vacaciones | AA26: 15 días
T27: Periodo prueba | V27: 6 meses | Y27: Costes seg. social | AA27: 436.59
K28: Convenio aplicable al sector | T28: Horario | V28: 08:00 - 15:00 | Y28: Costes s.s. autónom. | AA28: 0
T29: Jornada | V29: Completa | Y29: Fecha de inicio | AA29: 40648
B31: Area 3 | D31: Dependientes de la Dirección de Marketing y Ventas: | T31: Trabajador 3
T32: Puesto | W32: Celia Rodriguez
B33: Funciones | K33: Contrato indefinido | T33: Funciones
B34: • Marketing. • Telemarketing. • Ventas. | T34: • Marketing.• Telemarketing.• Ventas.
T36: Perfil | V36: Agente comercial | Y36: Salario | AA36: 1323
B37: Puestos de trabajo | T37: Cat.profesional | V37: Agente comercial | Y37: Beneficios sociales | AA37: Ninguno
B38: 1 puesto de trabajo. | T38: Tipo contrato | V38: Contrato indefinido | Y38: Vacaciones | AA38: 15 días
T39: Periodo prueba | V39: 6 meses | Y39: Costes seg. social | AA39: 436.59
K40: 30% del Salario base. | T40: Horario | V40: 08.00 - 15:00 | Y40: Costes s.s. autónom. | AA40: 0
T41: Jornada | V41: Completa | Y41: Fecha de inicio | AA41: 40634
B43: Area 4 | D43: Dependiente de la Dirección de Desarrollo de Proyectos: | T43: Trabajador 4
T44: Puesto | W44: Iago López Gómez
B45: Funciones | K45: Externalización del área de Prevención de Riesgos laborales a la Empresa PREVENCIÓN S.L | T45: Funciones
B46: • Desarrollo de proyectos. • Investigación y desarrollo CMS. | T46: • Concept design •Dirección de diseño •Dirección de programación
T48: Perfil | V48: Diseñador y programador | Y48: Salario | AA48: 1323
B49: Puestos de trabajo | T49: Cat.profesional | V49: Diseñador y programador principal | Y49: Beneficios sociales | AA49: Ninguno
B50: 1 puesto de trabajo. | T50: Tipo contrato | V50: Contrato indefinido | Y50: Vacaciones | AA50: 15 días
T51: Periodo prueba | V51: 6 meses | Y51: Costes seg. social | AA51: 436.59
K52: La política de contratación de la empresa se rige por el principio de favorecer la zona de ubicación de la empresa en este sentido se ha fijado como directriz que la contratación de todo el personal necesario será residente en dicha zona. | T52: Horario | V52: 08:00 - 15:00 | Y52: Costes s.s. autónom. | AA52: 0
...

Sheet 5. P. JURIDICO MERCANTIL
B7: SOCIEDAD DE RESPONSABILIDAD LIMITADA con un capital social de 3100 euros | K7: Licencias urbanísticas
P9: Plazo de obtención | R9: Coste
K10: Licencia 1 | P10: 1 mes | R10: 150
K11: Licencia 2 | P11: =---P12---R11 -> 0 | R11: 0
B12: Régimen general de IVA e IMPUESTO DE SOCIEDADES | K12: Licencia 3 | P12: 0 | R12: 0
K14: Autorizac.administrativas
P16: Plazo de obtención | R16: Coste
B17: 560,2 ; 360,5 ; 780,2 | K17: Autorización 1 | P17: Ninguna | R17: 0
K18: Autorización 2 | P18: Ninguna | R18: 0
K19: Autorización 3 | P19: Ninguna | R19: 0
K21: Costes de gestión
B22: Régimen especial de autónomos
N23: Interna/Externa | P23: Coste | Q23: Período | R23: Coste año
K24: Gestión contable | N24: Externa | P24: 100 | Q24: 1 año | R24: 1200
B25: ORGANO DE ADMINISTRACION | K25: Gestión fiscal | N25: Externa | P25: 100 | Q25: 1 año | R25: 1200
K26: Gestión mercantil | N26: Interno | P26: 100 | Q26: 1 año | R26: 1200
B27: Administrador único | K27: Gestión laboral | N27: Externo | P27: 100 | Q27: 1 año | R27: 1200
K28: Asesoramiento jurídico | N28: Ninguno | P28: Ninguno | Q28: Ninguno | R28: Ninguno
K29: Seguros
L30: Responsabilidad civil | P30: Ninguno | Q30: Ninguno | R30: Ninguno
L31: Local comercial | P31: 100 | Q31: 2 años | R31: 1200
B32: El único socio de la empresa aparte de ser socio capitalista será socio trabajador | L32: Cambio de moneda | P32: Ninguno | Q32: Ninguno | R32: Ninguno
B37: La estrategia fijada para la gestión de la empresa gira entorno a la coordinación y participación de todas las personas integrantes en la misma.
B42: La actual sociedad ha registrado las siguientes marcas y patentes: - IBS CMS, Internet Business Services, Ibs.es, Ibs.com y 14 derivados similares.
B47: La empresa tiene previsto la contratación de un seguro de responsabilidad para el local de ubicación de sus instalaciones.
B52: Solicitud de licencia para despacho profesional. Estado: en tramitación

Sheet 6. PEF1. PLAN COMERCIAL
C9: MESES | D9: Mes 1 | E9: Mes 2 | F9: Mes 3 | G9: Mes 4 | H9: Mes 5 | I9: Mes 6
C10: Ventas | D10: ='2. P. MARKETING'!BO25 -> 25000 | E10: ='2. P. MARKETING'!BQ25 -> 15000 | F10: ='2. P. MARKETING'!BS25 -> 12000 | G10: ='2. P. MARKETING'!BU25 -> 10000 | H10: ='2. P. MARKETING'!BW25 -> 10000 | I10: ='2. P. MARKETING'!BY25 -> 8000
D11: Mes 7 | E11: Mes 8 | F11: Mes 9 | G11: Mes 10 | H11: Mes 11 | I11: Mes 12
D12: ='2. P. MARKETING'!BO29 -> 6000 | E12: ='2. P. MARKETING'!BQ29 -> 6000 | F12: ='2. P. MARKETING'!BS29 -> 15000 | G12: ='2. P. MARKETING'!BU29 -> 7500 | H12: ='2. P. MARKETING'!BW29 -> 5000 | I12: ='2. P. MARKETING'!BY29 -> 6500
C14: Previsión tres primeros años | D14: Año 1 | E14: Año 2 | F14: Año 3
D15: =SUM(D10:I10,D12:I12) -> 126000 | E15: =D15*(1+$F$28) -> 144900 | F15: =E15*(1+$F$28) -> 166635
C19: MESES | D19: Mes 1 | E19: Mes 2 | F19: Mes 3 | G19: Mes 4 | H19: Mes 5 | I19: Mes 6
C20: Compras | D20: ='2. P. MARKETING'!BO35 -> 200 | E20: ='2. P. MARKETING'!BQ35 -> 200 | F20: ='2. P. MARKETING'!BS35 -> 250 | G20: ='2. P. MARKETING'!BU35 -> 250 | H20: ='2. P. MARKETING'!BW35 -> 250 | I20: ='2. P. MARKETING'!BY35 -> 250
D21: Mes 7 | E21: Mes 8 | F21: Mes 9 | G21: Mes 10 | H21: Mes 11 | I21: Mes 12
D22: ='2. P. MARKETING'!BO39 -> 250 | E22: ='2. P. MARKETING'!BQ39 -> 250 | F22: ='2. P. MARKETING'!BS39 -> 250 | G22: ='2. P. MARKETING'!BU39 -> 250 | H22: ='2. P. MARKETING'!BW39 -> 250 | I22: ='2. P. MARKETING'!BY39 -> 250
C24: Previsión tres primeros años | D24: Año 1 | E24: Año 2 | F24: Año 3
D25: =SUM(D20:I20,D22:I22) -> 2900 | E25: =D25*(1+$F$29) -> 3045 | F25: =E25*(1+$F$29) -> 3197.25
C28: Incremento anual previsto ventas (%) | F28: 0.15
C29: Incremento anual previsto compras (%) | F29: 0.05

Sheet 6. PEF2-3. INVERS. Y FINANC.
B9: INVERSIÓN | F9: INICIAL | I9: FINANCIACIÓN | N9: INICIAL
B11: ACTIVO FIJO | I11: RECURSOS PROPIOS
J12: Capital | N12: 14000
C13: Inmovilizado Inmaterial | G13: IVA | I13: EXIGIBLE A L/P
C14: Patentes y marcas | F14: 661.31 | G14: =67.69+71.19 -> 138.88 | J14: Préstamos a l/p | N14: 25000
C15: Derechos de traspaso | F15: 0 | G15: 0
C16: Aplicaciones informáticas | F16: 382.52 | G16: 60.82
C17: Leasing | F17: 0 | G17: 0
C18: Inmovilizado Material | J18: TOTAL Largo Plazo | N18: =SUM(N14:N17) -> 25000
C19: Terrenos | F19: 0 | G19: 0
C20: Construcciones | F20: 0 | G20: 0 | I20: EXIGIBLE A C/P
C21: Maquinaria | F21: 0 | G21: 0 | J21: Préstamos a c/p | N21: 15000
C22: Herramientas y útiles | F22: 0 | G22: 0
C23: Mobiliario | F23: 1000 | G23: 210
C24: Equipos informáticos | F24: 4318.21 | G24: 906.84
C25: Elementos de transporte | F25: 0 | G25: 0
C26: Otros | F26: 0 | G26: 0 | J26: TOTAL Corto Plazo | N26: =SUM(N21:N25) -> 15000
C27: Inmovilizado Financiero
C28: Fianzas | F28: 5250 | I28: TOTAL FINANCIACIÓN | N28: =N12+N18+N26 -> 54000
C29: TOTAL ACTIVO FIJO | F29: =SUM(F14:F17)+SUM(F19:F26)+F28 -> 11612.04
M30: =IF(N28=F42,"Balance cuadrado","Balance descuadrado") -> Balance cuadrado
B31: ACTIVO CIRCULANTE
C33: Existencias
C34: Existencias | F34: 0 | G34: 0
C35: Deudores
C36: Clientes | F36: 0 | G36: 0
C37: Administraciones públicas | F37: 0 | G37: 0
C38: Hacienda deudora por IVA | F38: =SUM(G14:G37) -> 1316.54
C39: Tesoreria | F39: 41071.42
C40: TOTAL ACTIVO CIRCULANTE | F40: =F34+SUM(F36:F39) -> 42387.96
B42: TOTAL INVERSIONES | F42: =F29+F40 -> 54000

Sheet 6.PEF4. AMORTIZACIÓN
B9: Prestamo | D9: Plazo (años) | E9: Tipo de interes (TAE) | G9: Año1 (*) | H9: Año 2 (*) | I9: Año 3 (*)
B10: ='6. PEF2-3. INVERS. Y FINANC.'!N14 -> 25000 | D10: 5 | E10: 0.045 | G10: =G13/12 -> 466.07548 | H10: =G10 -> 466.07548 | I10: =H10 -> 466.07548
C11: Principal | G11: =SUM('AMORTIZ. PTMO.'!D12:D23) -> 4561.218 | H11: =SUM('AMORTIZ. PTMO.'!D24:D35) -> 4770.7595 | I11: =SUM('AMORTIZ. PTMO.'!D36:D47) -> 4989.9274
C12: Intereses | G12: =SUM('AMORTIZ. PTMO.'!C12:C23) -> 1031.6878 | H12: =SUM('AMORTIZ. PTMO.'!C24:C35) -> 822.14623 | I12: =SUM('AMORTIZ. PTMO.'!C36:C47) -> 602.97837
C13: TOTAL | G13: =SUM(G11:G12) -> 5592.9058 | H13: =SUM(H11:H12) -> 5592.9058 | I13: =SUM(I11:I12) -> 5592.9058
B14: ='6. PEF2-3. INVERS. Y FINANC.'!N21 -> 15000 | D14: 1 | E14: 0.045 | G14: =G17/12 -> 1306.25 | H14: =H17/12 -> 0 | I14: =I17/12 -> 0
C15: Principal | G15: =B14 -> 15000 | H15: 0 | I15: 0
C16: Intereses | G16: =G15*E14 -> 675 | H16: 0 | I16: 0
C17: TOTAL | G17: =SUM(G15:G16) -> 15675 | H17: =SUM(H15:H16) -> 0 | I17: =SUM(I15:I16) -> 0
B19: Inmovilizado Inmaterial | E19: Coste | F19: Años | G19: Amort. Anual | H19: Año 2 | I19: Año3
B20: Patentes y marcas | E20: ='6. PEF2-3. INVERS. Y FINANC.'!F14 -> 661.31 | F20: 3 | G20: =E20/F20 -> 220.43667 | H20: =G20 -> 220.43667 | I20: =H20 -> 220.43667
B21: Derechos de traspaso | E21: ='6. PEF2-3. INVERS. Y FINANC.'!F15 -> 0 | F21: 3 | H21: =G21 -> 0 | I21: =H21 -> 0
B22: Aplicaciones informáticas | E22: ='6. PEF2-3. INVERS. Y FINANC.'!F16 -> 382.52 | F22: 3 | G22: =E22/F22 -> 127.50667 | H22: =G22 -> 127.50667 | I22: =H22 -> 127.50667
B23: Leasing | E23: ='6. PEF2-3. INVERS. Y FINANC.'!F17 -> 0 | F23: 3 | H23: =G23 -> 0 | I23: =H23 -> 0
B24: Inmovilizado Material | H24: =G24 -> 0 | I24: =H24 -> 0
B25: Terrenos | E25: ='6. PEF2-3. INVERS. Y FINANC.'!F19 -> 0 | F25: 3 | H25: =G25 -> 0 | I25: =H25 -> 0
B26: Construcciones | E26: ='6. PEF2-3. INVERS. Y FINANC.'!F20 -> 0 | F26: 3 | G26: =E26/F26 -> 0 | H26: =G26 -> 0 | I26: =H26 -> 0
B27: Maquinaria | E27: ='6. PEF2-3. INVERS. Y FINANC.'!F21 -> 0 | F27: 3 | G27: =E27/F27 -> 0 | H27: =G27 -> 0 | I27: =H27 -> 0
B28: Herramientas y útiles | E28: ='6. PEF2-3. INVERS. Y FINANC.'!F22 -> 0 | F28: 3 | G28: =E28/F28 -> 0 | H28: =G28 -> 0 | I28: =H28 -> 0
B29: Mobiliario | E29: ='6. PEF2-3. INVERS. Y FINANC.'!F23 -> 1000 | F29: 3 | G29: =E29/F29 -> 333.33333 | H29: =G29 -> 333.33333 | I29: =H29 -> 333.33333
B30: Equipos informáticos | E30: ='6. PEF2-3. INVERS. Y FINANC.'!F24 -> 4318.21 | F30: 3 | G30: =E30/F30 -> 1439.4033 | H30: =G30 -> 1439.4033 | I30: =H30 -> 1439.4033
B31: Fianzas | E31: ='6. PEF2-3. INVERS. Y FINANC.'!F28 -> 5250
B32: Otros | E32: ='6. PEF2-3. INVERS. Y FINANC.'!F26 -> 0 | F32: 3 | G32: =E32/F32 -> 0 | H32: =G32 -> 0 | I32: =H32 -> 0
B33: TOTAL AMORTIZACIÓN | E33: =SUM(E20:E32)-E31 -> 6362.04 | G33: =SUM(G20:G32) -> 2120.68 | H33: =SUM(H20:H32) -> 2120.68 | I33: =SUM(I20:I32) -> 2120.68
B36: (*) | C36: Cuota calculada mediante tabla de amortización de préstamo

Sheet 6. PEF5. VENTAS Y COSTES
C9: CONCEPTOS | F9: AÑO 1 | G9: AÑO 2 | H9: AÑO 3
C11: VENTAS (A) | F11: ='6. PEF1. PLAN COMERCIAL'!D15 -> 126000 | G11: ='6. PEF1. PLAN COMERCIAL'!E15 -> 144900 | H11: ='6. PEF1. PLAN COMERCIAL'!F15 -> 166635
C13: COSTES VARIABLES (B) | F13: =F15+F14+F16 -> 53704 | G13: =G15+G14+G16 -> 56389.2 | H13: =H15+H14+H16 -> 59208.66
C14: Consumo materias primas o productos | F14: ='6. PEF1. PLAN COMERCIAL'!D25 -> 2900 | G14: ='6. PEF1. PLAN COMERCIAL'!E25 -> 3045 | H14: ='6. PEF1. PLAN COMERCIAL'!F25 -> 3197.25
C15: Mano de obra directa | F15: 50803 | G15: =F15*(1+F42) -> 53343.15 | H15: =G15*(1+F42) -> 56010.308
C16: Otros gastos generales de fabricación o de prestación de servicios | F16: 1 | G16: =F16*(1+F43) -> 1.05 | H16: =G16*(1+F42) -> 1.1025
C18: MARGEN BRUTO (C = A – B) | F18: =F11-F13 -> 72296 | G18: =G11-G13 -> 88510.8 | H18: =H11-H13 -> 107426.34
C20: COSTES FIJOS (D): (sin incluir intereses) | F20: =SUM(F21:F31) -> 66065.68 | G20: =SUM(G21:G31) -> 69263.03 | H20: =SUM(H21:H31) -> 72620.262
C21: Arrendamientos | F21: 50 | G21: =F21*(1+F43) -> 52.5 | H21: =G21*(1+F43) -> 55.125
C22: Comunicación | F22: 1 | G22: =F22*(1+F43) -> 1.05 | H22: =G22*(1+F43) -> 1.1025
C23: Transportes | F23: 384 | G23: =F23*(1+F43) -> 403.2 | H23: =G23*(1+F43) -> 423.36
C24: Servicios de profesionales independientes | F24: 23814 | G24: =F24*(1+F43) -> 25004.7 | H24: =G24*(1+F43) -> 26254.935
C25: Material oficina | F25: 520 | G25: =F25*(1+F43) -> 546 | H25: =G25*(1+F43) -> 573.3
C26: Reparaciones y conservación | F26: 2500 | G26: =F26*(1+F43) -> 2625 | H26: =G26*(1+F43) -> 2756.25
C27: Suministros | F27: 1 | G27: =F27*(1+F43) -> 1.05 | H27: =G27*(1+F43) -> 1.1025
C28: Mano de obra indirecta (salarios + S.S.) | F28: 36673 | G28: =F28*(1+F43) -> 38506.65 | H28: =G28*(1+F43) -> 40431.983
C29: Tributos | F29: 1 | G29: =F29*(1+F44) -> 1.15 | H29: =G29*(1+F44) -> 1.3225
C30: Amortizaciones | F30: ='6.PEF4. AMORTIZACIÓN'!G33 -> 2120.68 | G30: ='6.PEF4. AMORTIZACIÓN'!G33 -> 2120.68 | H30: ='6.PEF4. AMORTIZACIÓN'!G33 -> 2120.68
C31: Otros gastos | F31: 1 | G31: =F31*(1+F43) -> 1.05 | H31: =G31*(1+F43) -> 1.1025
C42: Incremento previsto costes variables (%) | F42: ='6. PEF1. PLAN COMERCIAL'!F29 -> 0.05
C43: Incremento previsto costes fijos (%) | F43: 0.05
C44: Impuesto de sociedades | F44: 0.15

Sheet 6.PEF6. EXPLOTACION
I4: HOJA 1 | R4: HOJA 2 | AA4: HOJA 3 | AJ4: HOJA 4 | AS4: HOJA 5 | BB4: HOJA 6 | BJ4: HOJA 7
B8: CONCEPTO | D8: Mes 1 | E8: Mes 2 | F8: Mes 3 | G8: Mes 4 | H8: Mes 5 | I8: Mes 6 | K8: CONCEPTO | M8: Mes 7 | N8: Mes 8 | O8: Mes 9 | P8: Mes 10 | Q8: Mes 11 | R8: Mes 12 | T8: CONCEPTO | V8: Mes 13 | W8: Mes 14 | X8: Mes 15 | Y8: Mes 16 | Z8: Mes 17 | AA8: Mes 18 | AC8: CONCEPTO | AE8: Mes 19 | AF8: Mes 20 | AG8: Mes 21 | AH8: Mes 22 | AI8: Mes 23 | AJ8: Mes 24 | AL8: CONCEPTO | AN8: Mes 25 | AO8: Mes 26 | AP8: Mes 27 | AQ8: Mes 28 | AR8: Mes 29 | AS8: Mes 30 | AU8: CONCEPTO | AW8: Mes 31 | AX8: Mes 32 | AY8: Mes 33 | AZ8: Mes 34 | BA8: Mes 35 | BB8: Mes 36 | BD8: CONCEPTO | BF8: Total año 1 | BG8: Total año 2 | BH8: Total año 3
B10: Ventas | D10: ='6. PEF1. PLAN COMERCIAL'!D10 -> 25000 | E10: ='6. PEF1. PLAN COMERCIAL'!E10 -> 15000 | F10: ='6. PEF1. PLAN COMERCIAL'!F10 -> 12000 | G10: ='6. PEF1. PLAN COMERCIAL'!G10 -> 10000 | H10: ='6. PEF1. PLAN COMERCIAL'!H10 -> 10000 | I10: ='6. PEF1. PLAN COMERCIAL'!I10 -> 8000 | K10: Ventas | M10: ='6. PEF1. PLAN COMERCIAL'!D12 -> 6000 | N10: ='6. PEF1. PLAN COMERCIAL'!E12 -> 6000 | O10: ='6. PEF1. PLAN COMERCIAL'!F12 -> 15000 | P10: ='6. PEF1. PLAN COMERCIAL'!G12 -> 7500 | Q10: ='6. PEF1. PLAN COMERCIAL'!H12 -> 5000 | R10: ='6. PEF1. PLAN COMERCIAL'!I12 -> 6500 | T10: Ventas | V10: =D10*(1+'6. PEF1. PLAN COMERCIAL'!$F$28) -> 28750 | W10: =E10*(1+'6. PEF1. PLAN COMERCIAL'!$F$28) -> 17250 | X10: =F10*(1+'6. PEF1. PLAN COMERCIAL'!$F$28) -> 13800 | Y10: =G10*(1+'6. PEF1. PLAN COMERCIAL'!$F$28) -> 11500 | Z10: =H10*(1+'6. PEF1. PLAN COMERCIAL'!$F$28) -> 11500 | AA10: =I10*(1+'6. PEF1. PLAN COMERCIAL'!$F$28) -> 9200 | AC10: Ventas | AE10: =M10*(1+'6. PEF1. PLAN COMERCIAL'!$F$28) -> 6900 | AF10: =N10*(1+'6. PEF1. PLAN COMERCIAL'!$F$28) -> 6900 | AG10: =O10*(1+'6. PEF1. PLAN COMERCIAL'!$F$28) -> 17250 | AH10: =P10*(1+'6. PEF1. PLAN COMERCIAL'!$F$28) -> 8625 | AI10: =Q10*(1+'6. PEF1. PLAN COMERCIAL'!$F$28) -> 5750 | AJ10: =R10*(1+'6. PEF1. PLAN COMERCIAL'!$F$28) -> 7475 | AL10: Ventas | AN10: =V10*(1+'6. PEF1. PLAN COMERCIAL'!$F$28) -> 33062.5 | AO10: =W10*(1+'6. PEF1. PLAN COMERCIAL'!$F$28) -> 19837.5 | AP10: =X10*(1+'6. PEF1. PLAN COMERCIAL'!$F$28) -> 15870 | AQ10: =Y10*(1+'6. PEF1. PLAN COMERCIAL'!$F$28) -> 13225 | AR10: =Z10*(1+'6. PEF1. PLAN COMERCIAL'!$F$28) -> 13225 | AS10: =AA10*(1+'6. PEF1. PLAN COMERCIAL'!$F$28) -> 10580 | AU10: Ventas | AW10: =AE10*(1+'6. PEF1. PLAN COMERCIAL'!$F$28) -> 7935 | AX10: =AF10*(1+'6. PEF1. PLAN COMERCIAL'!$F$28) -> 7935 | AY10: =AG10*(1+'6. PEF1. PLAN COMERCIAL'!$F$28) -> 19837.5 | AZ10: =AH10*(1+'6. PEF1. PLAN COMERCIAL'!$F$28) -> 9918.75 | BA10: =AI10*(1+'6. PEF1. PLAN COMERCIAL'!$F$28) -> 6612.5 | BB10: =AJ10*(1+'6. PEF1. PLAN COMERCIAL'!$F$28) -> 8596.25 | BD10: Ventas | BF10: =SUM(D10:I10)+SUM(M10:R10) -> 126000 | BG10: =SUM(V10:AA10)+SUM(AE10:AJ10) -> 144900 | BH10: =SUM(AN10:AS10)+SUM(AW10:BB10) -> 166635
B11: Coste de las ventas | D11: ='6. PEF1. PLAN COMERCIAL'!D20 -> 200 | E11: ='6. PEF1. PLAN COMERCIAL'!E20 -> 200 | F11: ='6. PEF1. PLAN COMERCIAL'!F20 -> 250 | G11: ='6. PEF1. PLAN COMERCIAL'!G20 -> 250 | H11: ='6. PEF1. PLAN COMERCIAL'!H20 -> 250 | I11: ='6. PEF1. PLAN COMERCIAL'!I20 -> 250 | K11: Por compras | M11: ='6. PEF1. PLAN COMERCIAL'!D22 -> 250 | N11: ='6. PEF1. PLAN COMERCIAL'!E22 -> 250 | O11: ='6. PEF1. PLAN COMERCIAL'!F22 -> 250 | P11: ='6. PEF1. PLAN COMERCIAL'!G22 -> 250 | Q11: ='6. PEF1. PLAN COMERCIAL'!H22 -> 250 | R11: ='6. PEF1. PLAN COMERCIAL'!I22 -> 250 | T11: Por compras | V11: =D11*(1+'6. PEF1. PLAN COMERCIAL'!$F$29) -> 210 | W11: =E11*(1+'6. PEF1. PLAN COMERCIAL'!$F$29) -> 210 | X11: =F11*(1+'6. PEF1. PLAN COMERCIAL'!$F$29) -> 262.5 | Y11: =G11*(1+'6. PEF1. PLAN COMERCIAL'!$F$29) -> 262.5 | Z11: =H11*(1+'6. PEF1. PLAN COMERCIAL'!$F$29) -> 262.5 | AA11: =I11*(1+'6. PEF1. PLAN COMERCIAL'!$F$29) -> 262.5 | AC11: Por compras | AE11: =M11*(1+'6. PEF1. PLAN COMERCIAL'!$F$29) -> 262.5 | AF11: =N11*(1+'6. PEF1. PLAN COMERCIAL'!$F$29) -> 262.5 | AG11: =O11*(1+'6. PEF1. PLAN COMERCIAL'!$F$29) -> 262.5 | AH11: =P11*(1+'6. PEF1. PLAN COMERCIAL'!$F$29) -> 262.5 | AI11: =Q11*(1+'6. PEF1. PLAN COMERCIAL'!$F$29) -> 262.5 | AJ11: =R11*(1+'6. PEF1. PLAN COMERCIAL'!$F$29) -> 262.5 | AL11: Por compras | AN11: =V11*(1+'6. PEF1. PLAN COMERCIAL'!$F$29) -> 220.5 | AO11: =W11*(1+'6. PEF1. PLAN COMERCIAL'!$F$29) -> 220.5 | AP11: =X11*(1+'6. PEF1. PLAN COMERCIAL'!$F$29) -> 275.625 | AQ11: =Y11*(1+'6. PEF1. PLAN COMERCIAL'!$F$29) -> 275.625 | AR11: =Z11*(1+'6. PEF1. PLAN COMERCIAL'!$F$29) -> 275.625 | AS11: =AA11*(1+'6. PEF1. PLAN COMERCIAL'!$F$29) -> 275.625 | AU11: Por compras | AW11: =AE11*(1+'6. PEF1. PLAN COMERCIAL'!$F$29) -> 275.625 | AX11: =AF11*(1+'6. PEF1. PLAN COMERCIAL'!$F$29) -> 275.625 | AY11: =AG11*(1+'6. PEF1. PLAN COMERCIAL'!$F$29) -> 275.625 | AZ11: =AH11*(1+'6. PEF1. PLAN COMERCIAL'!$F$29) -> 275.625 | BA11: =AI11*(1+'6. PEF1. PLAN COMERCIAL'!$F$29) -> 275.625 | BB11: =AJ11*(1+'6. PEF1. PLAN COMERCIAL'!$F$29) -> 275.625 | BD11: Por compras | BF11: =SUM(D11:I11)+SUM(M11:R11) -> 2900 | BG11: =SUM(V11:AA11)+SUM(AE11:AJ11) -> 3045 | BH11: =SUM(AN11:AS11)+SUM(AW11:BB11) -> 3197.25
B12: Mano de obra directa | D12: =(('6. PEF5. VENTAS Y COSTES'!$F$15+'6. PEF5. VENTAS Y COSTES'!$F$16)/12) -> 4233.6667 | E12: =(('6. PEF5. VENTAS Y COSTES'!$F$15+'6. PEF5. VENTAS Y COSTES'!$F$16)/12) -> 4233.6667 | F12: =(('6. PEF5. VENTAS Y COSTES'!$F$15+'6. PEF5. VENTAS Y COSTES'!$F$16)/12) -> 4233.6667 | G12: =(('6. PEF5. VENTAS Y COSTES'!$F$15+'6. PEF5. VENTAS Y COSTES'!$F$16)/12) -> 4233.6667 | H12: =(('6. PEF5. VENTAS Y COSTES'!$F$15+'6. PEF5. VENTAS Y COSTES'!$F$16)/12) -> 4233.6667 | I12: =(('6. PEF5. VENTAS Y COSTES'!$F$15+'6. PEF5. VENTAS Y COSTES'!$F$16)/12) -> 4233.6667 | K12: Mano de obra directa | M12: =(('6. PEF5. VENTAS Y COSTES'!$F$15+'6. PEF5. VENTAS Y COSTES'!$F$16)/12) -> 4233.6667 | N12: =(('6. PEF5. VENTAS Y COSTES'!$F$15+'6. PEF5. VENTAS Y COSTES'!$F$16)/12) -> 4233.6667 | O12: =(('6. PEF5. VENTAS Y COSTES'!$F$15+'6. PEF5. VENTAS Y COSTES'!$F$16)/12) -> 4233.6667 | P12: =(('6. PEF5. VENTAS Y COSTES'!$F$15+'6. PEF5. VENTAS Y COSTES'!$F$16)/12) -> 4233.6667 | Q12: =(('6. PEF5. VENTAS Y COSTES'!$F$15+'6. PEF5. VENTAS Y COSTES'!$F$16)/12) -> 4233.6667 | R12: =(('6. PEF5. VENTAS Y COSTES'!$F$15+'6. PEF5. VENTAS Y COSTES'!$F$16)/12) -> 4233.6667 | T12: Mano de obra directa | V12: =(('6. PEF5. VENTAS Y COSTES'!$G$15+'6. PEF5. VENTAS Y COSTES'!$G$16)/12) -> 4445.35 | W12: =(('6. PEF5. VENTAS Y COSTES'!$G$15+'6. PEF5. VENTAS Y COSTES'!$G$16)/12) -> 4445.35 | X12: =(('6. PEF5. VENTAS Y COSTES'!$G$15+'6. PEF5. VENTAS Y COSTES'!$G$16)/12) -> 4445.35 | Y12: =(('6. PEF5. VENTAS Y COSTES'!$G$15+'6. PEF5. VENTAS Y COSTES'!$G$16)/12) -> 4445.35 | Z12: =(('6. PEF5. VENTAS Y COSTES'!$G$15+'6. PEF5. VENTAS Y COSTES'!$G$16)/12) -> 4445.35 | AA12: =(('6. PEF5. VENTAS Y COSTES'!$G$15+'6. PEF5. VENTAS Y COSTES'!$G$16)/12) -> 4445.35 | AC12: Mano de obra directa | AE12: =(('6. PEF5. VENTAS Y COSTES'!$G$15+'6. PEF5. VENTAS Y COSTES'!$G$16)/12) -> 4445.35 | AF12: =(('6. PEF5. VENTAS Y COSTES'!$G$15+'6. PEF5. VENTAS Y COSTES'!$G$16)/12) -> 4445.35 | AG12: =(('6. PEF5. VENTAS Y COSTES'!$G$15+'6. PEF5. VENTAS Y COSTES'!$G$16)/12) -> 4445.35 | AH12: =(('6. PEF5. VENTAS Y COSTES'!$G$15+'6. PEF5. VENTAS Y COSTES'!$G$16)/12) -> 4445.35 | AI12: =(('6. PEF5. VENTAS Y COSTES'!$G$15+'6. PEF5. VENTAS Y COSTES'!$G$16)/12) -> 4445.35 | AJ12: =(('6. PEF5. VENTAS Y COSTES'!$G$15+'6. PEF5. VENTAS Y COSTES'!$G$16)/12) -> 4445.35 | AL12: Mano de obra directa | AN12: =(('6. PEF5. VENTAS Y COSTES'!$H$15+'6. PEF5. VENTAS Y COSTES'!$H$16)/12) -> 4667.6175 | AO12: =(('6. PEF5. VENTAS Y COSTES'!$H$15+'6. PEF5. VENTAS Y COSTES'!$H$16)/12) -> 4667.6175 | AP12: =(('6. PEF5. VENTAS Y COSTES'!$H$15+'6. PEF5. VENTAS Y COSTES'!$H$16)/12) -> 4667.6175 | AQ12: =(('6. PEF5. VENTAS Y COSTES'!$H$15+'6. PEF5. VENTAS Y COSTES'!$H$16)/12) -> 4667.6175 | AR12: =(('6. PEF5. VENTAS Y COSTES'!$H$15+'6. PEF5. VENTAS Y COSTES'!$H$16)/12) -> 4667.6175 | AS12: =(('6. PEF5. VENTAS Y COSTES'!$H$15+'6. PEF5. VENTAS Y COSTES'!$H$16)/12) -> 4667.6175 | AU12: Mano de obra directa | AW12: =(('6. PEF5. VENTAS Y COSTES'!$H$15+'6. PEF5. VENTAS Y COSTES'!$H$16)/12) -> 4667.6175 | AX12: =(('6. PEF5. VENTAS Y COSTES'!$H$15+'6. PEF5. VENTAS Y COSTES'!$H$16)/12) -> 4667.6175 | AY12: =(('6. PEF5. VENTAS Y COSTES'!$H$15+'6. PEF5. VENTAS Y COSTES'!$H$16)/12) -> 4667.6175 | AZ12: =(('6. PEF5. VENTAS Y COSTES'!$H$15+'6. PEF5. VENTAS Y COSTES'!$H$16)/12) -> 4667.6175 | BA12: =(('6. PEF5. VENTAS Y COSTES'!$H$15+'6. PEF5. VENTAS Y COSTES'!$H$16)/12) -> 4667.6175 | BB12: =(('6. PEF5. VENTAS Y COSTES'!$H$15+'6. PEF5. VENTAS Y COSTES'!$H$16)/12) -> 4667.6175 | BD12: Mano de obra directa | BF12: =SUM(D12:I12)+SUM(M12:R12) -> 50804 | BG12: =SUM(V12:AA12)+SUM(AE12:AJ12) -> 53344.2 | BH12: =SUM(AN12:AS12)+SUM(AW12:BB12) -> 56011.41
B13: Margen bruto | D13: =D10-D11-D12 -> 20566.333 | E13: =E10-E11-E12 -> 10566.333 | F13: =F10-F11-F12 -> 7516.3333 | G13: =G10-G11-G12 -> 5516.3333 | H13: =H10-H11-H12 -> 5516.3333 | I13: =I10-I11-I12 -> 3516.3333 | K13: Margen bruto | M13: =M10-M11-M12 -> 1516.3333 | N13: =N10-N11-N12 -> 1516.3333 | O13: =O10-O11-O12 -> 10516.333 | P13: =P10-P11-P12 -> 3016.3333 | Q13: =Q10-Q11-Q12 -> 516.33333 | R13: =R10-R11-R12 -> 2016.3333 | T13: Margen bruto | V13: =V10-V11-V12 -> 24094.65 | W13: =W10-W11-W12 -> 12594.65 | X13: =X10-X11-X12 -> 9092.15 | Y13: =Y10-Y11-Y12 -> 6792.15 | Z13: =Z10-Z11-Z12 -> 6792.15 | AA13: =AA10-AA11-AA12 -> 4492.15 | AC13: Margen bruto | AE13: =AE10-AE11-AE12 -> 2192.15 | AF13: =AF10-AF11-AF12 -> 2192.15 | AG13: =AG10-AG11-AG12 -> 12542.15 | AH13: =AH10-AH11-AH12 -> 3917.15 | AI13: =AI10-AI11-AI12 -> 1042.15 | AJ13: =AJ10-AJ11-AJ12 -> 2767.15 | AL13: Margen bruto | AN13: =AN10-AN11-AN12 -> 28174.382 | AO13: =AO10-AO11-AO12 -> 14949.382 | AP13: =AP10-AP11-AP12 -> 10926.757 | AQ13: =AQ10-AQ11-AQ12 -> 8281.7575 | AR13: =AR10-AR11-AR12 -> 8281.7575 | AS13: =AS10-AS11-AS12 -> 5636.7575 | AU13: Margen bruto | AW13: =AW10-AW11-AW12 -> 2991.7575 | AX13: =AX10-AX11-AX12 -> 2991.7575 | AY13: =AY10-AY11-AY12 -> 14894.257 | AZ13: =AZ10-AZ11-AZ12 -> 4975.5075 | BA13: =BA10-BA11-BA12 -> 1669.2575 | BB13: =BB10-BB11-BB12 -> 3653.0075 | BD13: Margen bruto | BF13: =BF10-BF11-BF12 -> 72296 | BG13: =BG10-BG11-BG12 -> 88510.8 | BH13: =BH10-BH11-BH12 -> 107426.34
B14: M. obra indirecta (salarios + S.S.) | D14: ='6. PEF5. VENTAS Y COSTES'!$F$28/12 -> 3056.0833 | E14: ='6. PEF5. VENTAS Y COSTES'!$F$28/12 -> 3056.0833 | F14: ='6. PEF5. VENTAS Y COSTES'!$F$28/12 -> 3056.0833 | G14: ='6. PEF5. VENTAS Y COSTES'!$F$28/12 -> 3056.0833 | H14: ='6. PEF5. VENTAS Y COSTES'!$F$28/12 -> 3056.0833 | I14: ='6. PEF5. VENTAS Y COSTES'!$F$28/12 -> 3056.0833 | K14: M. obra indirecta (salarios + S.S.) | M14: ='6. PEF5. VENTAS Y COSTES'!$F$28/12 -> 3056.0833 | N14: ='6. PEF5. VENTAS Y COSTES'!$F$28/12 -> 3056.0833 | O14: ='6. PEF5. VENTAS Y COSTES'!$F$28/12 -> 3056.0833 | P14: ='6. PEF5. VENTAS Y COSTES'!$F$28/12 -> 3056.0833 | Q14: ='6. PEF5. VENTAS Y COSTES'!$F$28/12 -> 3056.0833 | R14: ='6. PEF5. VENTAS Y COSTES'!$F$28/12 -> 3056.0833 | T14: M. obra indirecta (salarios + S.S.) | V14: ='6. PEF5. VENTAS Y COSTES'!$G$28/12 -> 3208.8875 | W14: ='6. PEF5. VENTAS Y COSTES'!$G$28/12 -> 3208.8875 | X14: ='6. PEF5. VENTAS Y COSTES'!$G$28/12 -> 3208.8875 | Y14: ='6. PEF5. VENTAS Y COSTES'!$G$28/12 -> 3208.8875 | Z14: ='6. PEF5. VENTAS Y COSTES'!$G$28/12 -> 3208.8875 | AA14: ='6. PEF5. VENTAS Y COSTES'!$G$28/12 -> 3208.8875 | AC14: M. obra indirecta (salarios + S.S.) | AE14: ='6. PEF5. VENTAS Y COSTES'!$G$28/12 -> 3208.8875 | AF14: ='6. PEF5. VENTAS Y COSTES'!$G$28/12 -> 3208.8875 | AG14: ='6. PEF5. VENTAS Y COSTES'!$G$28/12 -> 3208.8875 | AH14: ='6. PEF5. VENTAS Y COSTES'!$G$28/12 -> 3208.8875 | AI14: ='6. PEF5. VENTAS Y COSTES'!$G$28/12 -> 3208.8875 | AJ14: ='6. PEF5. VENTAS Y COSTES'!$G$28/12 -> 3208.8875 | AL14: M. obra indirecta (salarios + S.S.) | AN14: ='6. PEF5. VENTAS Y COSTES'!$H$28/12 -> 3369.3319 | AO14: ='6. PEF5. VENTAS Y COSTES'!$H$28/12 -> 3369.3319 | AP14: ='6. PEF5. VENTAS Y COSTES'!$H$28/12 -> 3369.3319 | AQ14: ='6. PEF5. VENTAS Y COSTES'!$H$28/12 -> 3369.3319 | AR14: ='6. PEF5. VENTAS Y COSTES'!$H$28/12 -> 3369.3319 | AS14: ='6. PEF5. VENTAS Y COSTES'!$H$28/12 -> 3369.3319 | AU14: M. obra indirecta (salarios + S.S.) | AW14: ='6. PEF5. VENTAS Y COSTES'!$H$28/12 -> 3369.3319 | AX14: ='6. PEF5. VENTAS Y COSTES'!$H$28/12 -> 3369.3319 | AY14: ='6. PEF5. VENTAS Y COSTES'!$H$28/12 -> 3369.3319 | AZ14: ='6. PEF5. VENTAS Y COSTES'!$H$28/12 -> 3369.3319 | BA14: ='6. PEF5. VENTAS Y COSTES'!$H$28/12 -> 3369.3319 | BB14: ='6. PEF5. VENTAS Y COSTES'!$H$28/12 -> 3369.3319 | BD14: M. obra indirecta (salarios + S.S.) | BF14: =SUM(D14:I14)+SUM(M14:R14) -> 36673 | BG14: =SUM(V14:AA14)+SUM(AE14:AJ14) -> 38506.65 | BH14: =SUM(AN14:AS14)+SUM(AW14:BB14) -> 40431.983
B15: Arrendamientos | D15: ='6. PEF5. VENTAS Y COSTES'!$F$21/12 -> 4.1666667 | E15: ='6. PEF5. VENTAS Y COSTES'!$F$21/12 -> 4.1666667 | F15: ='6. PEF5. VENTAS Y COSTES'!$F$21/12 -> 4.1666667 | G15: ='6. PEF5. VENTAS Y COSTES'!$F$21/12 -> 4.1666667 | H15: ='6. PEF5. VENTAS Y COSTES'!$F$21/12 -> 4.1666667 | I15: ='6. PEF5. VENTAS Y COSTES'!$F$21/12 -> 4.1666667 | K15: Arrendamientos | M15: ='6. PEF5. VENTAS Y COSTES'!$F$21/12 -> 4.1666667 | N15: ='6. PEF5. VENTAS Y COSTES'!$F$21/12 -> 4.1666667 | O15: ='6. PEF5. VENTAS Y COSTES'!$F$21/12 -> 4.1666667 | P15: ='6. PEF5. VENTAS Y COSTES'!$F$21/12 -> 4.1666667 | Q15: ='6. PEF5. VENTAS Y COSTES'!$F$21/12 -> 4.1666667 | R15: ='6. PEF5. VENTAS Y COSTES'!$F$21/12 -> 4.1666667 | T15: Arrendamientos | V15: ='6. PEF5. VENTAS Y COSTES'!$G$21/12 -> 4.375 | W15: ='6. PEF5. VENTAS Y COSTES'!$G$21/12 -> 4.375 | X15: ='6. PEF5. VENTAS Y COSTES'!$G$21/12 -> 4.375 | Y15: ='6. PEF5. VENTAS Y COSTES'!$G$21/12 -> 4.375 | Z15: ='6. PEF5. VENTAS Y COSTES'!$G$21/12 -> 4.375 | AA15: ='6. PEF5. VENTAS Y COSTES'!$G$21/12 -> 4.375 | AC15: Arrendamientos | AE15: ='6. PEF5. VENTAS Y COSTES'!$G$21/12 -> 4.375 | AF15: ='6. PEF5. VENTAS Y COSTES'!$G$21/12 -> 4.375 | AG15: ='6. PEF5. VENTAS Y COSTES'!$G$21/12 -> 4.375 | AH15: ='6. PEF5. VENTAS Y COSTES'!$G$21/12 -> 4.375 | AI15: ='6. PEF5. VENTAS Y COSTES'!$G$21/12 -> 4.375 | AJ15: ='6. PEF5. VENTAS Y COSTES'!$G$21/12 -> 4.375 | AL15: Arrendamientos | AN15: ='6. PEF5. VENTAS Y COSTES'!$H$21/12 -> 4.59375 | AO15: ='6. PEF5. VENTAS Y COSTES'!$H$21/12 -> 4.59375 | AP15: ='6. PEF5. VENTAS Y COSTES'!$H$21/12 -> 4.59375 | AQ15: ='6. PEF5. VENTAS Y COSTES'!$H$21/12 -> 4.59375 | AR15: ='6. PEF5. VENTAS Y COSTES'!$H$21/12 -> 4.59375 | AS15: ='6. PEF5. VENTAS Y COSTES'!$H$21/12 -> 4.59375 | AU15: Arrendamientos | AW15: ='6. PEF5. VENTAS Y COSTES'!$H$21/12 -> 4.59375 | AX15: ='6. PEF5. VENTAS Y COSTES'!$H$21/12 -> 4.59375 | AY15: ='6. PEF5. VENTAS Y COSTES'!$H$21/12 -> 4.59375 | AZ15: ='6. PEF5. VENTAS Y COSTES'!$H$21/12 -> 4.59375 | BA15: ='6. PEF5. VENTAS Y COSTES'!$H$21/12 -> 4.59375 | BB15: ='6. PEF5. VENTAS Y COSTES'!$H$21/12 -> 4.59375 | BD15: Arrendamientos | BF15: =SUM(D15:I15)+SUM(M15:R15) -> 50 | BG15: =SUM(V15:AA15)+SUM(AE15:AJ15) -> 52.5 | BH15: =SUM(AN15:AS15)+SUM(AW15:BB15) -> 55.125
B16: Comunicación | D16: ='6. PEF5. VENTAS Y COSTES'!$F$22/12 -> 0.083333333 | E16: ='6. PEF5. VENTAS Y COSTES'!$F$22/12 -> 0.083333333 | F16: ='6. PEF5. VENTAS Y COSTES'!$F$22/12 -> 0.083333333 | G16: ='6. PEF5. VENTAS Y COSTES'!$F$22/12 -> 0.083333333 | H16: ='6. PEF5. VENTAS Y COSTES'!$F$22/12 -> 0.083333333 | I16: ='6. PEF5. VENTAS Y COSTES'!$F$22/12 -> 0.083333333 | K16: Comunicación | M16: ='6. PEF5. VENTAS Y COSTES'!$F$22/12 -> 0.083333333 | N16: ='6. PEF5. VENTAS Y COSTES'!$F$22/12 -> 0.083333333 | O16: ='6. PEF5. VENTAS Y COSTES'!$F$22/12 -> 0.083333333 | P16: ='6. PEF5. VENTAS Y COSTES'!$F$22/12 -> 0.083333333 | Q16: ='6. PEF5. VENTAS Y COSTES'!$F$22/12 -> 0.083333333 | R16: ='6. PEF5. VENTAS Y COSTES'!$F$22/12 -> 0.083333333 | T16: Comunicación | V16: ='6. PEF5. VENTAS Y COSTES'!$G$22/12 -> 0.0875 | W16: ='6. PEF5. VENTAS Y COSTES'!$G$22/12 -> 0.0875 | X16: ='6. PEF5. VENTAS Y COSTES'!$G$22/12 -> 0.0875 | Y16: ='6. PEF5. VENTAS Y COSTES'!$G$22/12 -> 0.0875 | Z16: ='6. PEF5. VENTAS Y COSTES'!$G$22/12 -> 0.0875 | AA16: ='6. PEF5. VENTAS Y COSTES'!$G$22/12 -> 0.0875 | AC16: Comunicación | AE16: ='6. PEF5. VENTAS Y COSTES'!$G$22/12 -> 0.0875 | AF16: ='6. PEF5. VENTAS Y COSTES'!$G$22/12 -> 0.0875 | AG16: ='6. PEF5. VENTAS Y COSTES'!$G$22/12 -> 0.0875 | AH16: ='6. PEF5. VENTAS Y COSTES'!$G$22/12 -> 0.0875 | AI16: ='6. PEF5. VENTAS Y COSTES'!$G$22/12 -> 0.0875 | AJ16: ='6. PEF5. VENTAS Y COSTES'!$G$22/12 -> 0.0875 | AL16: Comunicación | AN16: ='6. PEF5. VENTAS Y COSTES'!$H$22/12 -> 0.091875 | AO16: ='6. PEF5. VENTAS Y COSTES'!$H$22/12 -> 0.091875 | AP16: ='6. PEF5. VENTAS Y COSTES'!$H$22/12 -> 0.091875 | AQ16: ='6. PEF5. VENTAS Y COSTES'!$H$22/12 -> 0.091875 | AR16: ='6. PEF5. VENTAS Y COSTES'!$H$22/12 -> 0.091875 | AS16: ='6. PEF5. VENTAS Y COSTES'!$H$22/12 -> 0.091875 | AU16: Comunicación | AW16: ='6. PEF5. VENTAS Y COSTES'!$H$22/12 -> 0.091875 | AX16: ='6. PEF5. VENTAS Y COSTES'!$H$22/12 -> 0.091875 | AY16: ='6. PEF5. VENTAS Y COSTES'!$H$22/12 -> 0.091875 | AZ16: ='6. PEF5. VENTAS Y COSTES'!$H$22/12 -> 0.091875 | BA16: ='6. PEF5. VENTAS Y COSTES'!$H$22/12 -> 0.091875 | BB16: ='6. PEF5. VENTAS Y COSTES'!$H$22/12 -> 0.091875 | BD16: Comunicación | BF16: =SUM(D16:I16)+SUM(M16:R16) -> 1 | BG16: =SUM(V16:AA16)+SUM(AE16:AJ16) -> 1.05 | BH16: =SUM(AN16:AS16)+SUM(AW16:BB16) -> 1.1025
B17: Transportes | D17: ='6. PEF5. VENTAS Y COSTES'!$F$23/12 -> 32 | E17: ='6. PEF5. VENTAS Y COSTES'!$F$23/12 -> 32 | F17: ='6. PEF5. VENTAS Y COSTES'!$F$23/12 -> 32 | G17: ='6. PEF5. VENTAS Y COSTES'!$F$23/12 -> 32 | H17: ='6. PEF5. VENTAS Y COSTES'!$F$23/12 -> 32 | I17: ='6. PEF5. VENTAS Y COSTES'!$F$23/12 -> 32 | K17: Transportes | M17: ='6. PEF5. VENTAS Y COSTES'!$F$23/12 -> 32 | N17: ='6. PEF5. VENTAS Y COSTES'!$F$23/12 -> 32 | O17: ='6. PEF5. VENTAS Y COSTES'!$F$23/12 -> 32 | P17: ='6. PEF5. VENTAS Y COSTES'!$F$23/12 -> 32 | Q17: ='6. PEF5. VENTAS Y COSTES'!$F$23/12 -> 32 | R17: ='6. PEF5. VENTAS Y COSTES'!$F$23/12 -> 32 | T17: Transportes | V17: ='6. PEF5. VENTAS Y COSTES'!$G$23/12 -> 33.6 | W17: ='6. PEF5. VENTAS Y COSTES'!$G$23/12 -> 33.6 | X17: ='6. PEF5. VENTAS Y COSTES'!$G$23/12 -> 33.6 | Y17: ='6. PEF5. VENTAS Y COSTES'!$G$23/12 -> 33.6 | Z17: ='6. PEF5. VENTAS Y COSTES'!$G$23/12 -> 33.6 | AA17: ='6. PEF5. VENTAS Y COSTES'!$G$23/12 -> 33.6 | AC17: Transportes | AE17: ='6. PEF5. VENTAS Y COSTES'!$G$23/12 -> 33.6 | AF17: ='6. PEF5. VENTAS Y COSTES'!$G$23/12 -> 33.6 | AG17: ='6. PEF5. VENTAS Y COSTES'!$G$23/12 -> 33.6 | AH17: ='6. PEF5. VENTAS Y COSTES'!$G$23/12 -> 33.6 | AI17: ='6. PEF5. VENTAS Y COSTES'!$G$23/12 -> 33.6 | AJ17: ='6. PEF5. VENTAS Y COSTES'!$G$23/12 -> 33.6 | AL17: Transportes | AN17: ='6. PEF5. VENTAS Y COSTES'!$H$23/12 -> 35.28 | AO17: ='6. PEF5. VENTAS Y COSTES'!$H$23/12 -> 35.28 | AP17: ='6. PEF5. VENTAS Y COSTES'!$H$23/12 -> 35.28 | AQ17: ='6. PEF5. VENTAS Y COSTES'!$H$23/12 -> 35.28 | AR17: ='6. PEF5. VENTAS Y COSTES'!$H$23/12 -> 35.28 | AS17: ='6. PEF5. VENTAS Y COSTES'!$H$23/12 -> 35.28 | AU17: Transportes | AW17: ='6. PEF5. VENTAS Y COSTES'!$H$23/12 -> 35.28 | AX17: ='6. PEF5. VENTAS Y COSTES'!$H$23/12 -> 35.28 | AY17: ='6. PEF5. VENTAS Y COSTES'!$H$23/12 -> 35.28 | AZ17: ='6. PEF5. VENTAS Y COSTES'!$H$23/12 -> 35.28 | BA17: ='6. PEF5. VENTAS Y COSTES'!$H$23/12 -> 35.28 | BB17: ='6. PEF5. VENTAS Y COSTES'!$H$23/12 -> 35.28 | BD17: Transportes | BF17: =SUM(D17:I17)+SUM(M17:R17) -> 384 | BG17: =SUM(V17:AA17)+SUM(AE17:AJ17) -> 403.2 | BH17: =SUM(AN17:AS17)+SUM(AW17:BB17) -> 423.36
B18: Serv. Profesionales | D18: ='6. PEF5. VENTAS Y COSTES'!$F$24/12 -> 1984.5 | E18: ='6. PEF5. VENTAS Y COSTES'!$F$24/12 -> 1984.5 | F18: ='6. PEF5. VENTAS Y COSTES'!$F$24/12 -> 1984.5 | G18: ='6. PEF5. VENTAS Y COSTES'!$F$24/12 -> 1984.5 | H18: ='6. PEF5. VENTAS Y COSTES'!$F$24/12 -> 1984.5 | I18: ='6. PEF5. VENTAS Y COSTES'!$F$24/12 -> 1984.5 | K18: Serv. Profesionales | M18: ='6. PEF5. VENTAS Y COSTES'!$F$24/12 -> 1984.5 | N18: ='6. PEF5. VENTAS Y COSTES'!$F$24/12 -> 1984.5 | O18: ='6. PEF5. VENTAS Y COSTES'!$F$24/12 -> 1984.5 | P18: ='6. PEF5. VENTAS Y COSTES'!$F$24/12 -> 1984.5 | Q18: ='6. PEF5. VENTAS Y COSTES'!$F$24/12 -> 1984.5 | R18: ='6. PEF5. VENTAS Y COSTES'!$F$24/12 -> 1984.5 | T18: Serv. Profesionales | V18: ='6. PEF5. VENTAS Y COSTES'!$G$24/12 -> 2083.725 | W18: ='6. PEF5. VENTAS Y COSTES'!$G$24/12 -> 2083.725 | X18: ='6. PEF5. VENTAS Y COSTES'!$G$24/12 -> 2083.725 | Y18: ='6. PEF5. VENTAS Y COSTES'!$G$24/12 -> 2083.725 | Z18: ='6. PEF5. VENTAS Y COSTES'!$G$24/12 -> 2083.725 | AA18: ='6. PEF5. VENTAS Y COSTES'!$G$24/12 -> 2083.725 | AC18: Serv. Profesionales | AE18: ='6. PEF5. VENTAS Y COSTES'!$G$24/12 -> 2083.725 | AF18: ='6. PEF5. VENTAS Y COSTES'!$G$24/12 -> 2083.725 | AG18: ='6. PEF5. VENTAS Y COSTES'!$G$24/12 -> 2083.725 | AH18: ='6. PEF5. VENTAS Y COSTES'!$G$24/12 -> 2083.725 | AI18: ='6. PEF5. VENTAS Y COSTES'!$G$24/12 -> 2083.725 | AJ18: ='6. PEF5. VENTAS Y COSTES'!$G$24/12 -> 2083.725 | AL18: Serv. Profesionales | AN18: ='6. PEF5. VENTAS Y COSTES'!$H$24/12 -> 2187.9113 | AO18: ='6. PEF5. VENTAS Y COSTES'!$H$24/12 -> 2187.9113 | AP18: ='6. PEF5. VENTAS Y COSTES'!$H$24/12 -> 2187.9113 | AQ18: ='6. PEF5. VENTAS Y COSTES'!$H$24/12 -> 2187.9113 | AR18: ='6. PEF5. VENTAS Y COSTES'!$H$24/12 -> 2187.9113 | AS18: ='6. PEF5. VENTAS Y COSTES'!$H$24/12 -> 2187.9113 | AU18: Serv. Profesionales | AW18: ='6. PEF5. VENTAS Y COSTES'!$H$24/12 -> 2187.9113 | AX18: ='6. PEF5. VENTAS Y COSTES'!$H$24/12 -> 2187.9113 | AY18: ='6. PEF5. VENTAS Y COSTES'!$H$24/12 -> 2187.9113 | AZ18: ='6. PEF5. VENTAS Y COSTES'!$H$24/12 -> 2187.9113 | BA18: ='6. PEF5. VENTAS Y COSTES'!$H$24/12 -> 2187.9113 | BB18: ='6. PEF5. VENTAS Y COSTES'!$H$24/12 -> 2187.9113 | BD18: Serv. Profesionales | BF18: =SUM(D18:I18)+SUM(M18:R18) -> 23814 | BG18: =SUM(V18:AA18)+SUM(AE18:AJ18) -> 25004.7 | BH18: =SUM(AN18:AS18)+SUM(AW18:BB18) -> 26254.935
B19: Material oficina | D19: ='6. PEF5. VENTAS Y COSTES'!$F$25/12 -> 43.333333 | E19: ='6. PEF5. VENTAS Y COSTES'!$F$25/12 -> 43.333333 | F19: ='6. PEF5. VENTAS Y COSTES'!$F$25/12 -> 43.333333 | G19: ='6. PEF5. VENTAS Y COSTES'!$F$25/12 -> 43.333333 | H19: ='6. PEF5. VENTAS Y COSTES'!$F$25/12 -> 43.333333 | I19: ='6. PEF5. VENTAS Y COSTES'!$F$25/12 -> 43.333333 | K19: Material oficina | M19: ='6. PEF5. VENTAS Y COSTES'!$F$25/12 -> 43.333333 | N19: ='6. PEF5. VENTAS Y COSTES'!$F$25/12 -> 43.333333 | O19: ='6. PEF5. VENTAS Y COSTES'!$F$25/12 -> 43.333333 | P19: ='6. PEF5. VENTAS Y COSTES'!$F$25/12 -> 43.333333 | Q19: ='6. PEF5. VENTAS Y COSTES'!$F$25/12 -> 43.333333 | R19: ='6. PEF5. VENTAS Y COSTES'!$F$25/12 -> 43.333333 | T19: Material oficina | V19: ='6. PEF5. VENTAS Y COSTES'!$G$25/12 -> 45.5 | W19: ='6. PEF5. VENTAS Y COSTES'!$G$25/12 -> 45.5 | X19: ='6. PEF5. VENTAS Y COSTES'!$G$25/12 -> 45.5 | Y19: ='6. PEF5. VENTAS Y COSTES'!$G$25/12 -> 45.5 | Z19: ='6. PEF5. VENTAS Y COSTES'!$G$25/12 -> 45.5 | AA19: ='6. PEF5. VENTAS Y COSTES'!$G$25/12 -> 45.5 | AC19: Material oficina | AE19: ='6. PEF5. VENTAS Y COSTES'!$G$25/12 -> 45.5 | AF19: ='6. PEF5. VENTAS Y COSTES'!$G$25/12 -> 45.5 | AG19: ='6. PEF5. VENTAS Y COSTES'!$G$25/12 -> 45.5 | AH19: ='6. PEF5. VENTAS Y COSTES'!$G$25/12 -> 45.5 | AI19: ='6. PEF5. VENTAS Y COSTES'!$G$25/12 -> 45.5 | AJ19: ='6. PEF5. VENTAS Y COSTES'!$G$25/12 -> 45.5 | AL19: Material oficina | AN19: ='6. PEF5. VENTAS Y COSTES'!$H$25/12 -> 47.775 | AO19: ='6. PEF5. VENTAS Y COSTES'!$H$25/12 -> 47.775 | AP19: ='6. PEF5. VENTAS Y COSTES'!$H$25/12 -> 47.775 | AQ19: ='6. PEF5. VENTAS Y COSTES'!$H$25/12 -> 47.775 | AR19: ='6. PEF5. VENTAS Y COSTES'!$H$25/12 -> 47.775 | AS19: ='6. PEF5. VENTAS Y COSTES'!$H$25/12 -> 47.775 | AU19: Material oficina | AW19: ='6. PEF5. VENTAS Y COSTES'!$H$25/12 -> 47.775 | AX19: ='6. PEF5. VENTAS Y COSTES'!$H$25/12 -> 47.775 | AY19: ='6. PEF5. VENTAS Y COSTES'!$H$25/12 -> 47.775 | AZ19: ='6. PEF5. VENTAS Y COSTES'!$H$25/12 -> 47.775 | BA19: ='6. PEF5. VENTAS Y COSTES'!$H$25/12 -> 47.775 | BB19: ='6. PEF5. VENTAS Y COSTES'!$H$25/12 -> 47.775 | BD19: Material oficina | BF19: =SUM(D19:I19)+SUM(M19:R19) -> 520 | BG19: =SUM(V19:AA19)+SUM(AE19:AJ19) -> 546 | BH19: =SUM(AN19:AS19)+SUM(AW19:BB19) -> 573.3
